# 异常

### 错误恢复

错误恢复机制是提高代码健壮性的最强有力的方式。发现错误的理想时机是在编译阶段，也就是在你试图运行程序之前。然而，编译期间并不能找出所有的错误，余下的问题必须在运行期间解决。这就需要错误源能通过某种方式，把适当的信息传递给某个接收者——该接收者将知道如何正确处理这个问题。

Java 使用异常来提供一致的错误报告模型，使得构件能够与客户端代码可靠地沟通问题。Java 中的异常处理的目的在于通过使用少于目前数量的代码来简化大型、可靠的程序的生成，并且通过这种方式可以使你更加确信：你的应用中没有未处理的错误。异常的相关知识学起来并非艰涩难懂，并且它属于那种可以使你的项目受益明显、立竿见影的特性之一。

### 基本异常

异常情形是指阻止当前方法或作用域继续执行的问题。把异常情形与普通问题相区分很重要，所谓的普通问题是指，在当前环境下能得到足够的信息，总能处理这个错误。而对于异常情形，不能继续下去了，因为在当前环境下无法获得必要的信息来解决问题。你所能做的就是从当前环境跳出，并且把问题提交给上一级环境，这就是抛出异常时所发生的事情。

当抛出异常后，有几件事会随之发生。首先，同 Java 中其他对象的创建一样，将使用 new 在堆上创建异常对象。然后，当前的执行路径（它不能继续下去了）被终止，并且从当前环境中弹出对异常对象的引用。此时，异常处理机制接管程序，并开始寻找一个恰当的地方来继续执行程序。这个恰当的地方就是异常处理程序，它的任务是将程序从错误状态中恢复，以使程序能要么换一种方式运行，要么继续运行下去。

### 异常构造

与使用 Java 中的其他对象一样，我们总是用 new 在堆上创建异常对象，这也伴随着存储空间的分配和构造器的调用。所有标准异常类都有两个构造器：一个是无参构造器；另一个是接受字符串作为参数，以便能把相关信息放入异常对象的构造器：

```` java
if(t == null)
    throw new NullPointerException();
````

关键字 `throw` 将产生许多有趣的结果。在使用 new 创建了异常对象之后，此对象的引用将传给 throw。尽管异常对象的类型通常与方法设计的返回类型不同，但从效果上看，它就像是从方法“返回”的。可以简单地把异常处理看成一种不同的返回机制，当然若过分强调这种类比的话，就会有麻烦了。另外还能用抛出异常的方式从当前的作用域退出。在这两种情况下，将会返回一个异常对象，然后退出方法或作用域。

异常返回的“地点”与普通方法调用返回的“地点”完全不同。（异常将在一个恰当的异常处理程序中得到解决，它的位置可能离异常被抛出的地方很远，也可能会跨越方法调用栈的许多层级。）

### 自定义异常

```` java
class MyException extends Exception {
    MyException() {}
    MyException(String msg) { super(msg); }
}
public class FullConstructors {
    public static void f() throws MyException {
        System.out.println("Throwing MyException from f()");
        throw new MyException();
    }
    public static void g() throws MyException {
        System.out.println("Throwing MyException from g()");
        throw new MyException("Originated in g()");
    }
    public static void main(String[] args) {
        try {
            f();
        } catch (MyException e) {
            e.printStackTrace(System.out);
        }
        try {
            g();
        } catch (MyException e) {
            e.printStackTrace(System.out);
        }
    }
}
/* Output:
Throwing MyException from f()
MyException
    at FullConstructors.f(FullConstructors.java:11)
    at FullConstructors.main(FullConstructors.java:19)
Throwing MyException from g()
MyException: Originated in g()
    at FullConstructors.g(FullConstructors.java:15)
    at FullConstructors.main(FullConstructors.java:24)
*/
````

自定义异常的代码非常简短：两个构造器定义了 MyException 类型对象的创建方式。对于第二个构造器，使用 super 关键字明确调用了其基类构造器，它接受一个字符串作为参数。

在异常处理程序中，调用了在 Throwable 类声明（Exception 即从此类继承）的 printStackTrace() 方法。就像从输出中看到的，它将打印“从方法调用处直到异常抛出处”的方法调用序列。这里，信息被发送到了 System.out，并自动地被捕获和显示在输出中。

### 异常声明

Java 鼓励人们把方法可能会抛出的异常告知使用此方法的客户端程序员，Java 提供了相应的语法（并强制使用这个语法），使你能以礼貌的方式告知客户端程序员某个方法可能会抛出的异常类型，然后客户端程序员就可以进行相应的处理。这就是异常声明，它属于方法声明的一部分，紧跟在形式参数列表之后。

异常声明使用了附加的关键字 `throws`，后面接一个所有潜在异常类型的列表，所以方法定义可能看起来像这样：

```` java
void f() throws TooBig, TooSmall, DivZero { // ...
````

但是，要是这样写：

```` java
void f() { // ...
````

就表示此方法不会抛出任何异常（除了从 RuntimeException 继承的异常，它们可以在没有异常声明的情况下被抛出，这些将在后面进行讨论）。

### 异常捕获

如果在方法内部抛出了异常，这个方法将在抛出异常结束。如果不希望方法就此结束，可以在方法内设置一个特殊的块来捕获异常。因为在这个块里“尝试”各种可能产生异常的方法调用，所以称为 `try` 块。它是跟在 try 关键字之后的普通程序块。

```` java
try {
    // do somethings that might generate exceptions
}
````
抛出的异常必须在某处得到处理，这个“地点”就是异常处理程序，异常处理程序紧跟在 try 块之后，以关键字 `catch` 表示。

```` java
try {
    // do somethings that might generate exceptions
} catch (Exception1 exception1) {
    // Handle exceptions of Exception1
} catch (Exception2 exception2) {
    // Handle exceptions of Exception2
} catch (Exception3 exception3) {
    // Handle exceptions of Exception3
}
````

异常处理程序必须紧跟在 try 块之后。当异常被抛出时，异常处理机制将负责搜寻参数与异常类型相匹配的第一个处理程序。然后进入 catch 子句执行，此时认为异常得到了处理一旦 catch 子句结束，则处理程序的查找过程结束。注意，只有匹配的 catch 子句才能得到执行；这与 switch 语句不同，switch 语句需要在每一个 case 后面跟一个 break，以避免执行后续的 case 子句。

如果有一组具有相同基类的异常，你想使用同一方式进行捕获，那你直接 catch 它们的基类型。但是，如果这些异常没有共同的基类型，在 Java 7 之前，你必须为每一个类型编写一个 catch。通过 Java 7 的多重捕获机制，你可以使用“或”将不同类型的异常组合起来，只需要一行 catch 语句。

```` java
public class MultiCatch {
    void x() throws Except1, Except2, Except3, Except4 {}
    void process1() {}
    void process2() {}
    void f() {
        try {
            x();
        } catch (Except1 | Except2 e) {
            process1();
        } catch (Except3 | Except4 e) {
            process2();
        }
    }
}
````

### 异常重抛

有时希望把刚捕获的异常重新抛出，尤其是在使用 Exception 捕获所有异常的时候。重抛异常会把异常抛给上一级环境中的异常处理程序，同一个 try 块的后续 catch 子句将被忽略。此外，异常对象的所有信息都得以保持，所以高一级环境中捕获此异常的处理程序可以从这个异常对象中得到所有信息。

如果只是把当前异常对象重新抛出，那么 printStackTrace() 方法显示的将是原来异常抛出点的调用栈信息，而并非重新抛出点的信息。要想更新这个信息，可以调用 fillInStackTrace() 方法，这将返回一个 Throwable 对象，它是通过把当前调用栈信息填入原来那个异常对象而建立的，调用 fillInStackTrace() 的那一行就成了异常的新发生地了。

```` java
public class Rethrowing {
    public static void f() throws Exception {
        System.out.println(
                "originating the exception in f()");
        throw new Exception("thrown from f()");
    }
    public static void h() throws Exception {
        try {
            f();
        } catch (Exception e) {
            System.out.println(
                    "Inside h(), e.printStackTrace()");
            e.printStackTrace(System.out);
            throw (Exception)e.fillInStackTrace();
        }
    }
    public static void main(String[] args) {
        try {
            h();
        } catch (Exception e) {
            System.out.println("main: printStackTrace()");
            e.printStackTrace(System.out);
        }
    }
}
/* Output:
originating the exception in f()
Inside h(), e.printStackTrace()
java.lang.Exception: thrown from f()
	at Rethrowing.f(Rethrowing.java:12)
	at Rethrowing.h(Rethrowing.java:16)
	at Rethrowing.main(Rethrowing.java:26)
main: printStackTrace()
java.lang.Exception: thrown from f()
	at Rethrowing.h(Rethrowing.java:21)
	at Rethrowing.main(Rethrowing.java:26)
*/
````

也有可能在捕获异常之后抛出另一种异常。这么做的话，得到的效果类似于使用 fillInStackTrace()，有关原来异常发生点的信息会丢失，剩下的是与新的抛出点有关的信息。

### 标准异常

Throwable 这个 Java 类被用来表示任何可以作为异常被抛出的类。Throwable 对象可分为两种类型（指从 Throwable 继承而得到的类型）：Error 用来表示编译时和系统错误（除特殊情况外，一般不用你关心）；Exception 是可以被抛出的基本类型，在 Java 类库、用户方法以及运行时故障中都可能抛出 Exception 型异常，Java 程序员关心的基类型通常是 Exception。

```` java
if(t == null)
    throw new NullPointerException();
````

这是本章的一个例子，如果我们需要对每一个引用都校验 null，这听起来有点吓人。幸运的是我们并不需要这样做，如果对 null 引用进行调用，Java 会自动抛出 NullPointerException 异常。

NullPointerException 是 RuntimeException 的子类，属于运行时异常，它们被 java 自动抛出。 如果不捕获这种类型的异常程序也可以正常编译运行，因为编译器没有对 RuntimeException 进行强制检查，RuntimeException 类型的异常也许会穿越所有的执行路径直达主函数，而不会被捕获。


### finally

有一些代码片段，可能会希望无论 try 块中的异常是否抛出，它们都能得到执行，比如释放链接、本地资源等，为了达到这个效果，可以在异常处理程序后面加上 finally 子句。

```` java
try {
    // do somethings that might generate exceptions
} catch (Exception1 exception1) {
    // Handle exceptions of Exception1
} catch (Exception2 exception2) {
    // Handle exceptions of Exception2
} catch (Exception3 exception3) {
    // Handle exceptions of Exception3
} finally {
    // Activities that happen every time
}
````

为了证明finally块一定会执行，执行下面代码：

```` java
public class MyFinally {
    public static void main(String[] args) {
        int i = 4;
        while (i > 0) {
            System.out.println("main i:" + func(i));
            i--;
        }
    }

    public static int func(int i) {

        try {
            i *= i;
            if (i == 9) {
                System.out.println("return i:" + i);
                return i;
            }
            if (i == 4) {
                System.out.println("throw i:" + i);
                throw new Exception();
            }
        } catch (Exception e) {
            e.printStackTrace();
        } finally {
            System.out.println("finally i:" + i);
        }
        return i;
    }
}
/* Output:
finally i:16
main i:16
return i:9
finally i:9
main i:9
throw i:4
finally i:4
main i:4
finally i:1
main i:1
java.lang.Exception
	at MyFinally.func(MyFinally.java:27)
	at MyFinally.main(MyFinally.java:12)
*/
````

从输出中可以看出，无论是发生异常还是 try 代码块使用 return 关键字 finally 子句总能被执行。这也为解决 Java 不允许我们回到异常抛出点这一问题，提供了一个思路。要注意一点，如果在 finally 子句中使用 return 会覆盖 try 中 return 的值。

### try-with-resource

根据以往经验：try-finally 语句是确保资源会被适时关闭的最佳方法，就算发生异常或者返回也一样，但如果涉及多个资源代码就会显得一团糟。

```` java
static void copy(String src, String desc) throws IOException {
    InputStream in = new FileInputStream(src);
    try {
        OutputStream out = new FileOutputStream(desc);
        byte[] bytes = new byte[1024];
        int n;
        try {
            while ((n = in.read(bytes)) != -1) {
                out.write(bytes, 0, n);
            }
        } finally {
            out.close();
        }
    } finally {
        in.close();
    }
}
````

即便是 try-finally 语句正确的关闭了资源，如前两段代码所示，也存在不足，因为在 try 块和 finally 块的代码，都会抛出异常，例如，在 firstLineOfFile 方法中，如果底层的物理设备异常，那么调用 readLine 就会抛出异常，基于同样的原因，调用 close 也会出现异常，在这种情况下，第二个异常会完全抹去第一个异常。在异常堆栈轨迹中，完全没有关于第一个异常的记录，在现实中的系统的会导致调式变得非常复杂，因为通常需要看到第一个异常才能诊断出问题何在，虽然你可以通过编写代码来禁止第二个异常，但太过烦琐。

Java 7 引入了 try-with-resources 语句时解决了上述问题。要使用这个构造的资源，必须先实现 AutoCloseable 接口。其中包含了单个返回 void 的 close 方法，如果编写一个类，它表示的是必须被关闭的资源，那么这个类也应该实现 AutoCloseable 接口，Java 类库与第三方类库中的许多类和接口，现在都实现或扩展了 AutoCloseable 接口。

```` java
static void copy(String src, String desc) throws IOException {
    try (InputStream in = new FileInputStream(src);
         OutputStream out = new FileOutputStream(desc)) {
        byte[] bytes = new byte[1024];
        int n;
        while ((n = in.read(bytes)) != -1) {
            out.write(bytes, 0, n);
        }
    }
}
````

在 try-with-resources 语句中还可以使用 catch 语句，就像在 try-finally 中一样使用，这样既可以处理异常，又不需要再多套一层代码。

```` java
static String firstLineOfFile(String path, String defaultVal) {
    try (BufferedReader reader = new BufferedReader(new FileReader(path))) {
        return reader.readLine();
    } catch (IOException e) {
        return defaultVal;
    }
}
````

### 异常指南

应该在下列情况下使用异常：
- 尽可能使用 try-with-resource。
- 在恰当的级别处理问题。（在知道该如何处理的情况下才捕获异常。）
- 解决问题并且重新调用产生异常的方法。
- 进行少许修补，然后绕过异常发生的地方继续执行。
- 用别的数据进行计算，以代替方法预计会返回的值。
- 把当前运行环境下能做的事情尽量做完，然后把相同的异常重抛到更高层。
- 把当前运行环境下能做的事情尽量做完，然后把不同的异常抛到更高层。
- 终止程序。
- 进行简化。（如果你的异常模式使问题变得太复杂，那用起来会非常痛苦也很烦人。）
- 让类库和程序更安全。（这既是在为调试做短期投资，也是在为程序的健壮性做长期投资。）


